Workbook

Sheet Start here
B2: Empower manual quoting kit: timed pilot test
B4: What this is
B5: A test of the Empower Ops Agents app against the way quotes are made today. You will quote one client request twice: first by hand with this workbook, then with the app. We time both and you judge both. Your honest opinion is the point; there are no wrong answers.
B6: All people, projects and rates here are DEMO data that look like Empower's, not real. Judge the method and the result as if they were real.
B8: Part 1: quote it by hand (up to 40 minutes)
B9: 1. Write the start time in 'Scorecard' (cell C6) and read 'Client request'.
B10: 2. Work out the hours per role, a team and dates, and a price, the way you normally would. Fill the yellow cells in 'Quote worksheet'. It adds PM, tech lead, QA and contingency from the policy and does the price and margin sums for you.
B11: 3. Use the reference sheets as you would your own files: 'Rate card & policy', 'People & availability' (who is free each week), 'Module history' (what past modules actually took) and 'Past projects'.
B12: 4. Also note feasibility, the top risks and the questions you would ask the client.
B13: 5. Stop at a quote you would be willing to discuss internally, or at 40 minutes. Write the end time (C7). If you stopped early, write how long a proper quote would really take you (C8).
B15: Part 2: the same request in the app (about 15 minutes)
B16: 6. In the app, sign in as Director, open 'New deal', click the sample PDF 'brightsmile_rfp.pdf' (same request), and press 'Run Deal Desk'. Write the start time (C10) when you press Run.
... B25: Example of the format: in 'Quote worksheet', Backend Developer build hours = 640 (a number of hours, not a %).

Sheet Client request
B2: The client request (identical to the sample PDF in the app)
B4: Client | C4: BrightSmile Dental Group
B5: Country | C5: US
B6: Quote currency | C6: USD
B7: Received | C7: 2026-10-26 (the demo data's 'today')
B9: RFP (text of the PDF) | C9: BrightSmile Dental Group - Request for Proposal: Patient Booking App Issued by: Megan Walsh, COO, BrightSmile Dental Group (Ohio and Michigan, USA) Background and needs Hi Empower team, We run 14 dental clinics across Ohio and Michigan (BrightSmile Dental Group). Right now patients call the front desk to book, and our staff spend most of the morning on the phone. We want: 1. A patient app (iPhone + Android) and a matching website where patients can book, reschedule and cancel cleanings and appointments with a specific dentist or hygienist. 2. SMS and email reminders 48h and 2h before the visit, with a 'confirm' button. No-shows cost us a lot. 3. Patients should see their upcoming visits, past visit summaries and outstanding balance, and pay the balance by card. 4. A simple admin panel for front-desk staff to manage dentist schedules, block holidays and see the day's bookings per clinic. 5. Our practice management system is Dentrix; bookings need to sync with it (they have an API, we think). We obviously need this to be HIPAA compliant. We'd like to go live before our busy season in early April. Budget is not fixed but our board was thinking around $60-80k. Can you send a proposal with timeline and price? Thanks, Megan Walsh COO, BrightSmile Dental Group Evaluation Proposals will be compared on understanding of our needs, HIPAA approach, timeline, team and price. Please include assumptions and questions for us.

Sheet Quote worksheet
B2: Your quote: BrightSmile patient booking app
B3: Yellow = type here (blue text). Black = calculated. Green = pulled from 'Rate card & policy'.
B5: Quote currency | C5: USD | D5: USD, EUR or GBP
B6: Risk level | C6: medium | D6: low, medium or high: sets contingency (10% / 15% / 25%)
B7: Regulated data (HIPAA / PCI / GDPR)? | C7: No | D7: Yes adds 10% to QA hours
B8: Discount | C8: 0 | D8: Type 5% (or 0.05). Over 5% needs a director; 10% is the maximum
B9: Planned start date | D9: e.g. 2 Nov 2026
B10: Planned go-live date | D10: e.g. 30 Apr 2027
B11: Feasible? | D11: Yes / Yes with conditions / No
B12: Weeks from start to go-live | C12: =IF(AND(ISNUMBER(C9),ISNUMBER(C10)),(C10-C9)/7,0)
B14: Role | C14: Build hours (you enter) | D14: Hours incl. PM, lead, QA, contingency | E14: Rate / h | F14: Billing at list | G14: Internal cost / h (INR) | H14: Internal cost (INR)
B15: Business Analyst | C15: 0 | D15: =(C15)*$C$39 | E15: =INDEX('Rate card & policy'!$D$5:$F$15,MATCH($I15,'Rate card & policy'!$B$5:$B$15,0),MATCH($C$5,'Rate card & policy'!$D$4:$F$4,0)) | F15: =D15*E15 | G15: =INDEX('Rate card & policy'!$G$5:$G$15,MATCH($I15,'Rate card & policy'!$B$5:$B$15,0)) | H15: =D15*G15 | I15: ba
B16: UI/UX Designer | C16: 0 | D16: =(C16)*$C$39 | E16: =INDEX('Rate card & policy'!$D$5:$F$15,MATCH($I16,'Rate card & policy'!$B$5:$B$15,0),MATCH($C$5,'Rate card & policy'!$D$4:$F$4,0)) | F16: =D16*E16 | G16: =INDEX('Rate card & policy'!$G$5:$G$15,MATCH($I16,'Rate card & policy'!$B$5:$B$15,0)) | H16: =D16*G16 | I16: uiux
B17: Frontend Developer | C17: 0 | D17: =(C17)*$C$39 | E17: =INDEX('Rate card & policy'!$D$5:$F$15,MATCH($I17,'Rate card & policy'!$B$5:$B$15,0),MATCH($C$5,'Rate card & policy'!$D$4:$F$4,0)) | F17: =D17*E17 | G17: =INDEX('Rate card & policy'!$G$5:$G$15,MATCH($I17,'Rate card & policy'!$B$5:$B$15,0)) | H17: =D17*G17 | I17: fe
B18: Backend Developer | C18: 0 | D18: =(C18)*$C$39 | E18: =INDEX('Rate card & policy'!$D$5:$F$15,MATCH($I18,'Rate card & policy'!$B$5:$B$15,0),MATCH($C$5,'Rate card & policy'!$D$4:$F$4,0)) | F18: =D18*E18 | G18: =INDEX('Rate card & policy'!$G$5:$G$15,MATCH($I18,'Rate card & policy'!$B$5:$B$15,0)) | H18: =D18*G18 | I18: be
B19: Mobile Developer | C19: 0 | D19: =(C19)*$C$39 | E19: =INDEX('Rate card & policy'!$D$5:$F$15,MATCH($I19,'Rate card & policy'!$B$5:$B$15,0),MATCH($C$5,'Rate card & policy'!$D$4:$F$4,0)) | F19: =D19*E19 | G19: =INDEX('Rate card & policy'!$G$5:$G$15,MATCH($I19,'Rate card & policy'!$B$5:$B$15,0)) | H19: =D19*G19 | I19: mobile
B20: QA Engineer | C20: 0 | D20: =(C20+$C$31+$C$32)*$C$39 | E20: =INDEX('Rate card & policy'!$D$5:$F$15,MATCH($I20,'Rate card & policy'!$B$5:$B$15,0),MATCH($C$5,'Rate card & policy'!$D$4:$F$4,0)) | F20: =D20*E20 | G20: =INDEX('Rate card & policy'!$G$5:$G$15,MATCH($I20,'Rate card & policy'!$B$5:$B$15,0)) | H20: =D20*G20 | I20: qa
B21: DevOps / Cloud Engineer | C21: 0 | D21: =(C21)*$C$39 | E21: =INDEX('Rate card & policy'!$D$5:$F$15,MATCH($I21,'Rate card & policy'!$B$5:$B$15,0),MATCH($C$5,'Rate card & policy'!$D$4:$F$4,0)) | F21: =D21*E21 | G21: =INDEX('Rate card & policy'!$G$5:$G$15,MATCH($I21,'Rate card & policy'!$B$5:$B$15,0)) | H21: =D21*G21 | I21: devops
B22: Data / BI Engineer | C22: 0 | D22: =(C22)*$C$39 | E22: =INDEX('Rate card & policy'!$D$5:$F$15,MATCH($I22,'Rate card & policy'!$B$5:$B$15,0),MATCH($C$5,'Rate card & policy'!$D$4:$F$4,0)) | F22: =D22*E22 | G22: =INDEX('Rate card & policy'!$G$5:$G$15,MATCH($I22,'Rate card & policy'!$B$5:$B$15,0)) | H22: =D22*G22 | I22: data
B23: AI / ML Engineer | C23: 0 | D23: =(C23)*$C$39 | E23: =INDEX('Rate card & policy'!$D$5:$F$15,MATCH($I23,'Rate card & policy'!$B$5:$B$15,0),MATCH($C$5,'Rate card & policy'!$D$4:$F$4,0)) | F23: =D23*E23 | G23: =INDEX('Rate card & policy'!$G$5:$G$15,MATCH($I23,'Rate card & policy'!$B$5:$B$15,0)) | H23: =D23*G23 | I23: ml
B24: Project Manager | C24: added by policy | D24: =$C$34*$C$39 | E24: =INDEX('Rate card & policy'!$D$5:$F$15,MATCH($I24,'Rate card & policy'!$B$5:$B$15,0),MATCH($C$5,'Rate card & policy'!$D$4:$F$4,0)) | F24: =D24*E24 | G24: =INDEX('Rate card & policy'!$G$5:$G$15,MATCH($I24,'Rate card & policy'!$B$5:$B$15,0)) | H24: =D24*G24 | I24: pm
B25: Tech Lead / Architect | C25: added by policy | D25: =$C$35*$C$39 | E25: =INDEX('Rate card & policy'!$D$5:$F$15,MATCH($I25,'Rate card & policy'!$B$5:$B$15,0),MATCH($C$5,'Rate card & policy'!$D$4:$F$4,0)) | F25: =D25*E25 | G25: =INDEX('Rate card & policy'!$G$5:$G$15,MATCH($I25,'Rate card & policy'!$B$5:$B$15,0)) | H25: =D25*G25 | I25: lead
B26: Total | C26: =SUM(C15:C23) | D26: =SUM(D15:D25) | F26: =SUM(F15:F25) | H26: =SUM(H15:H25)
B28: How the hours are built up (policy rules)
B29: Development hours (FE, BE, mobile, DevOps, data, ML) | C29: =C17+C18+C19+C22+C23+C21
B30: QA needed (minimum share of dev hours) | C30: =C29*'Rate card & policy'!$J$10
B31: QA top-up to reach the minimum | C31: =MAX(0,C30-C20)
B32: Regulated-data QA uplift | C32: =IF($C$7="Yes",(C20+C31)*'Rate card & policy'!$J$11,0)
B33: Base hours (build + QA top-ups) | C33: =C26+C31+C32
B34: Project manager | C34: =C33*'Rate card & policy'!$J$8
B35: Tech lead | C35: =C33*'Rate card & policy'!$J$9
B36: Subtotal (expected hours) | C36: =C33+C34+C35
B37: Contingency % | C37: =INDEX('Rate card & policy'!$J$12:$J$14,MATCH($C$6,{"low","medium","high"},0))
B38: Total hours priced | C38: =C36*(1+C37)
B39: Scale factor (total / subtotal) | C39: =IF(C36>0,C38/C36,1)
B41: Price and margin
B42: Time & materials at list rates | C42: =F26
B43: Time & materials price (after discount, rounded) | C43: =ROUND(C42*(1-$C$8),-2)
B44: Fixed price (list + risk premium, after discount, rounded) | C44: =ROUND(C42*(1+'Rate card & policy'!$J$15)*(1-$C$8),-2)
B45: Internal delivery cost (in quote currency) | C45: =H26/INDEX('Rate card & policy'!$J$5:$J$7,MATCH($C$5,{"USD","EUR","GBP"},0))
...

Sheet Scorecard
B2: Scorecard: time and quality, by hand vs the app
B3: Yellow = type here. Times as hh:mm (e.g. 14:05). Ratings 1 (poor) to 5 (excellent).
B5: Timing | C5: Time | E5: Note
B6: Part 1 by hand: start
B7: Part 1 by hand: end
B8: If you stopped early: hours a proper quote would really take you | E8: Only if you stopped at the 40-minute limit
B9: Minutes spent by hand | C9: =IF(AND(ISNUMBER(C6),ISNUMBER(C7)),(C7-C6)*1440,0)
B10: Part 2 app: start (pressed Run)
B11: Part 2 app: formed a view
B12: Minutes with the app (run + reading) | C12: =IF(AND(ISNUMBER(C10),ISNUMBER(C11)),(C11-C10)*1440,0)
B13: How many days does a quote like this usually take at Empower, from email to sending? | E13: Ask yourself, not the app
B16: Rate each quote (1-5) | C16: By hand | D16: App | E16: Why (what was missing or wrong?)
B17: Example: Hours are realistic (format only) | C17: 3 | D17: 4 | E17: App's mobile hours look high; mine missed QA
B18: Hours are realistic for this work
B19: Team and dates are realistic (people actually free)
B20: Price is right for this client and within policy
B21: Risks and gaps were caught (e.g. Dentrix, HIPAA, deadline, budget)
B22: Questions for the client are the right ones
B23: Ready to send to the client after light editing
B24: Average | C24: =IF(COUNT(C18:C23)>0,AVERAGE(C18:C23),0) | D24: =IF(COUNT(D18:D23)>0,AVERAGE(D18:D23),0)
B26: Questions | C26: Answer
B27: Minutes of editing the app's proposal would need before you'd send it
B28: Would you use this for real quotes? (1 = never, 5 = every time)
B29: What did the app get wrong, or what would you not trust?
B30: What was most useful?
B31: One sentence I may quote in my course report
B32: May I quote you as (name + role, role only, or no)?
B33: Your role at Empower

Sheet Rate card & policy
B2: Rate card and pricing policy (demo)
D3: Billing rate per hour
B4: Role key | C4: Role | D4: USD | E4: EUR | F4: GBP | G4: Internal cost / h (INR) | I4: Policy | J4: Value
B5: pm | C5: Project Manager | D5: 38 | E5: 36 | F5: 31 | G5: 1726.4 | I5: INR per USD | J5: 88
B6: ba | C6: Business Analyst | D6: 32 | E6: 30 | F6: 26 | G6: 1060.3 | I6: INR per EUR | J6: 102
B7: uiux | C7: UI/UX Designer | D7: 30 | E7: 28 | F7: 25 | G7: 1075.4 | I7: INR per GBP | J7: 117
B8: fe | C8: Frontend Developer | D8: 28 | E8: 27 | F8: 23 | G8: 966.3 | I8: PM overhead | J8: 0.1
B9: be | C9: Backend Developer | D9: 30 | E9: 29 | F9: 25 | G9: 1272.4 | I9: Tech lead overhead | J9: 0.06
B10: mobile | C10: Mobile Developer | D10: 32 | E10: 30 | F10: 26 | G10: 802 | I10: Minimum QA (share of dev hours) | J10: 0.2
B11: qa | C11: QA Engineer | D11: 22 | E11: 21 | F11: 18 | G11: 1189.8 | I11: Extra QA for regulated data (HIPAA/PCI/GDPR) | J11: 0.1
B12: devops | C12: DevOps / Cloud Engineer | D12: 36 | E12: 34 | F12: 29 | G12: 885.1 | I12: Contingency: low risk | J12: 0.1
B13: data | C13: Data / BI Engineer | D13: 36 | E13: 34 | F13: 29 | G13: 1051.2 | I13: Contingency: medium risk | J13: 0.15
B14: ml | C14: AI / ML Engineer | D14: 45 | E14: 42 | F14: 37 | G14: 927.4 | I14: Contingency: high risk | J14: 0.25
B15: lead | C15: Tech Lead / Architect | D15: 45 | E15: 42 | F15: 37 | G15: 2186.3 | I15: Fixed-price risk premium | J15: 0.12
B16: Billing rates per hour from the demo rate card (data/seed/rate_card.json, as of 2026-10-01). | I16: Margin floor | J16: 0.35
I17: Target margin | J17: 0.5
I18: Discount without director approval (max) | J18: 0.05
I19: Maximum discount | J19: 0.1
I20: Discovery weeks | J20: 2
I21: Stabilisation weeks | J21: 2
I22: Warranty (days) | J22: 60
I23: Hours per week | J23: 40
I25: Fixed-price payment milestones
I26: Contract signature (mobilisation) | J26: 0.2
I27: Design + architecture sign-off | J27: 0.2
I28: Beta / UAT release | J28: 0.4
I29: Go-live | J29: 0.2
I31: T&M billing: Monthly in arrears against approved timesheets

Sheet People & availability
A1: People and free capacity per week (demo). 100 = fully free; planned leave counts as busy.
A3: ID | B3: Name | C3: Role | D3: Title | E3: Level | F3: Office | G3: Years | H3: Skills | I3: 26 Oct | J3: 02 Nov | K3: 09 Nov | L3: 16 Nov | M3: 23 Nov | N3: 30 Nov | O3: 07 Dec | P3: 14 Dec | Q3: 21 Dec | R3: 28 Dec | S3: 04 Jan | T3: 11 Jan
A4: E005 | B4: Aditya Deshmukh | C4: ba | D4: Mid Business Analyst | E4: Mid | F4: Indore | G4: 4 | H4: User stories, Power BI, Process mapping, Healthcare domain | I4: 50 | J4: 50 | K4: 50 | L4: 50 | M4: 50 | N4: 50 | O4: 50 | P4: 50 | Q4: 50 | R4: 0 | S4: 0 | T4: 0
A5: E006 | B5: Yash Bhatt | C5: ba | D5: Senior Business Analyst | E5: Senior | F5: Pune | G5: 11 | H5: Figma, SQL, Healthcare domain, User stories, Power BI | I5: 50 | J5: 50 | K5: 50 | L5: 50 | M5: 50 | N5: 50 | O5: 50 | P5: 50 | Q5: 50 | R5: 50 | S5: 50 | T5: 50
A6: E007 | B6: Swati Solanki | C6: ba | D6: Mid Business Analyst | E6: Mid | F6: Bhopal | G6: 6 | H6: Requirements, Fintech domain, Process mapping, Power BI | I6: 50 | J6: 50 | K6: 50 | L6: 50 | M6: 100 | N6: 100 | O6: 100 | P6: 100 | Q6: 100 | R6: 100 | S6: 100 | T6: 100
A7: E019 | B7: Vivek Porwal | C7: be | D7: Senior Backend Developer | E7: Senior | F7: Indore | G7: 9 | H7: Salesforce API, Redis, Django, FastAPI, Node.js | I7: 0 | J7: 0 | K7: 0 | L7: 0 | M7: 100 | N7: 100 | O7: 100 | P7: 100 | Q7: 100 | R7: 100 | S7: 100 | T7: 100
A8: E020 | B8: Rahul Parmar | C8: be | D8: Senior Backend Developer | E8: Senior | F8: Indore | G8: 9 | H8: ASP.NET MVC, REST APIs, Stripe, .NET Core, WebSockets | I8: 0 | J8: 0 | K8: 0 | L8: 0 | M8: 0 | N8: 0 | O8: 0 | P8: 0 | Q8: 0 | R8: 0 | S8: 0 | T8: 100
A9: E021 | B9: Tushar Nair | C9: be | D9: Senior Backend Developer | E9: Senior | F9: Indore | G9: 6 | H9: .NET Core, PostgreSQL, SQL Server, GraphQL, Elasticsearch | I9: 0 | J9: 0 | K9: 0 | L9: 0 | M9: 100 | N9: 100 | O9: 100 | P9: 100 | Q9: 100 | R9: 100 | S9: 100 | T9: 100
A10: E022 | B10: Tanvi Solanki | C10: be | D10: Mid Backend Developer | E10: Mid | F10: Bhopal | G10: 3 | H10: Python, .NET Core, Redis, Django | I10: 50 | J10: 50 | K10: 50 | L10: 50 | M10: 50 | N10: 50 | O10: 50 | P10: 50 | Q10: 0 | R10: 0 | S10: 50 | T10: 50
A11: E023 | B11: Pooja Dixit | C11: be | D11: Senior Backend Developer | E11: Senior | F11: Indore | G11: 6 | H11: C#, WebSockets, MongoDB, Python, Twilio | I11: 0 | J11: 0 | K11: 0 | L11: 0 | M11: 0 | N11: 0 | O11: 0 | P11: 0 | Q11: 0 | R11: 0 | S11: 0 | T11: 0
A12: E024 | B12: Pooja Sharma | C12: be | D12: Senior Backend Developer | E12: Senior | F12: Pune | G12: 11 | H12: PostgreSQL, Python, ASP.NET MVC, Twilio, SQL Server | I12: 50 | J12: 50 | K12: 50 | L12: 50 | M12: 50 | N12: 50 | O12: 50 | P12: 50 | Q12: 50 | R12: 50 | S12: 50 | T12: 50
A13: E025 | B13: Pooja Tiwari | C13: be | D13: Mid Backend Developer | E13: Mid | F13: Bhopal | G13: 5 | H13: Python, Stripe, ASP.NET MVC, Twilio | I13: 0 | J13: 0 | K13: 0 | L13: 0 | M13: 0 | N13: 0 | O13: 0 | P13: 100 | Q13: 100 | R13: 100 | S13: 100 | T13: 100
A14: E026 | B14: Akash Rajput | C14: be | D14: Mid Backend Developer | E14: Mid | F14: Indore | G14: 3 | H14: .NET Core, GraphQL, ASP.NET MVC, C# | I14: 0 | J14: 0 | K14: 0 | L14: 0 | M14: 0 | N14: 0 | O14: 0 | P14: 0 | Q14: 0 | R14: 0 | S14: 0 | T14: 0
A15: E027 | B15: Aditya Patil | C15: be | D15: Mid Backend Developer | E15: Mid | F15: Indore | G15: 4 | H15: ASP.NET MVC, REST APIs, Python, Twilio | I15: 50 | J15: 50 | K15: 50 | L15: 50 | M15: 50 | N15: 50 | O15: 50 | P15: 50 | Q15: 50 | R15: 100 | S15: 100 | T15: 100
... A57: E010 | B57: Pooja Patidar | C57: uiux | D57: Senior UI/UX Designer | E57: Senior | F57: Pune | G57: 9 | H57: Figma, Mobile UI, Accessibility (WCAG), Design systems, Prototyping | I57: 50 | J57: 50 | K57: 50 | L57: 50 | M57: 50 | N57: 50 | O57: 50 | P57: 50 | Q57: 50 | R57: 50 | S57: 50 | T57: 50
A59: Week columns start on the date shown (Monday). Values: % of the person's week not booked on projects or leave, from the demo assignments file.

Sheet Module history
A1: What past modules ACTUALLY took: median hours per role, normalised to medium complexity (demo)
A2: Scale by complexity: low x0.6, medium x1.0, high x1.6. 'Overrun' = how far past estimates for this module were below actuals. Rows with 0 past projects show the catalog starting point instead.
A4: Module key | B4: Module | C4: Past projects | D4: Past overrun | E4: Business Analyst | F4: UI/UX Designer | G4: Frontend Developer | H4: Backend Developer | I4: Mobile Developer | J4: QA Engineer | K4: DevOps / Cloud Engineer | L4: Data / BI Engineer | M4: AI / ML Engineer | N4: Total (build)
A5: admin_panel | B5: Admin panel & back office | C5: 8 | D5: 0.175 | E5: 19.6 | F5: 29.9 | G5: 99.1 | H5: 88.5 | J5: 48.4 | N5: =SUM(E5:M5)
A6: auth | B6: User accounts, login & roles | C6: 17 | D6: 0.173 | E6: 9.2 | F6: 14.4 | G6: 48.3 | H6: 65.8 | J6: 29.1 | N6: =SUM(E6:M6)
A7: booking | B7: Booking & scheduling engine | C7: 5 | D7: 0.224 | E7: 28.6 | F7: 27.7 | G7: 77.4 | H7: 137.4 | J7: 69.5 | N7: =SUM(E7:M7)
A8: bpm | B8: Workflow & approval engine (BPM) | C8: 2 | D8: 0.069 | E8: 39.4 | G8: 60.9 | H8: 116.2 | J8: 41 | N8: =SUM(E8:M8)
A9: cloud_infra | B9: Cloud infrastructure, CI/CD & environments | C9: 7 | D9: 0.203 | H9: 19.8 | K9: 100.7 | N9: =SUM(E9:M9)
A10: cms | B10: CMS & content management | C10: 5 | D10: 0.153 | F10: 21.2 | G10: 59.8 | H10: 49.3 | J10: 25.8 | N10: =SUM(E10:M10)
A11: compliance | B11: Audit logging & compliance controls | C11: 9 | D11: 0.202 | E11: 19.1 | H11: 76 | J11: 29.9 | K11: 30 | N11: =SUM(E11:M11)
A12: crm | B12: CRM workflows & customer records | C12: 1 | D12: 0.116 | E12: 40.7 | G12: 80 | H12: 133.1 | J12: 39.8 | N12: =SUM(E12:M12)
A13: ecommerce | B13: Product catalog, cart & checkout | C13: 2 | D13: 0.219 | F13: 34.4 | G13: 105.8 | H13: 122.8 | J13: 61.4 | N13: =SUM(E13:M13)
A14: etl | B14: Data pipeline / ETL | C14: 7 | D14: 0.142 | H14: 28 | J14: 26.8 | K14: 17.5 | L14: 133 | N14: =SUM(E14:M14)
A15: geo | B15: Maps, geolocation & route tracking | C15: 3 | D15: 0.236 | G15: 52.3 | H15: 69.7 | I15: 49.2 | J15: 30.7 | N15: =SUM(E15:M15)
A16: integration | B16: Third-party API integration | C16: 10 | D16: 0.238 | E16: 14.4 | H16: 89.5 | J16: 29.4 | N16: =SUM(E16:M16)
A17: iot | B17: IoT device ingestion & telemetry | C17: 3 | D17: 0.188 | H17: 120.5 | J17: 41.5 | K17: 55.2 | L17: 50.1 | N17: =SUM(E17:M17)
A18: llm_assistant | B18: LLM assistant / RAG chatbot | C18: 3 | D18: 0.305 | G18: 43.4 | H18: 62.5 | J18: 51.6 | M18: 165.2 | N18: =SUM(E18:M18)
A19: migration | B19: Legacy data migration | C19: 2 | D19: 0.225 | E19: 20 | H19: 48.2 | J19: 37.8 | L19: 80.2 | N19: =SUM(E19:M19)
A20: ml_model | B20: Predictive ML model | C20: 1 | D20: 0.32 | J20: 38.8 | L20: 83.5 | M20: 236.6 | N20: =SUM(E20:M20)
A21: mobile_app | B21: Mobile app (iOS + Android, cross-platform) | C21: 7 | D21: 0.168 | F21: 71.5 | H21: 46.6 | I21: 353.2 | J21: 134.8 | N21: =SUM(E21:M21)
A22: notifications | B22: Notifications (email, SMS, push) | C22: 6 | D22: 0.19 | H22: 45.5 | I22: 18.4 | J22: 18.6 | N22: =SUM(E22:M22)
A23: patient_records | B23: Patient records & care plans | C23: 1 | D23: 0.197 | E23: 43.9 | G23: 98.7 | H23: 157.7 | J23: 77.2 | N23: =SUM(E23:M23)
A24: payments | B24: Payments & billing integration | C24: 7 | D24: 0.212 | E24: 17.1 | G24: 37.2 | H24: 111 | J24: 55.3 | N24: =SUM(E24:M24)
A25: realtime | B25: Real-time sync & live updates | C25: 4 | D25: 0.099 | G25: 44.3 | H25: 89.4 | J25: 33.8 | K25: 18 | N25: =SUM(E25:M25)
A26: reporting | B26: Reporting & analytics dashboard | C26: 11 | D26: 0.141 | F26: 19 | G26: 60.7 | H26: 45.1 | J26: 27.9 | L26: 46.6 | N26: =SUM(E26:M26)
A27: search | B27: Search, filters & listings | C27: 6 | D27: 0.188 | G27: 47.2 | H27: 59.9 | J27: 21 | N27: =SUM(E27:M27)
A28: tracking | B28: Event tracking & pixel analytics | C28: 2 | D28: 0.109 | H28: 82 | J28: 24.3 | K28: 34 | L28: 80 | N28: =SUM(E28:M28)
A29: web_portal | B29: Customer-facing web portal (UI build) | C29: 10 | D29: 0.142 | E29: 19.9 | F29: 68.9 | G29: 191.3 | J29: 49.5 | N29: =SUM(E29:M29)

Sheet Past projects
A1: Past projects: estimated vs actual hours (demo)
A3: ID | B3: Project | C3: Client | D3: Country | E3: Type | F3: Stack | G3: Contract | H3: Cur. | I3: Price | J3: Est. hours | K3: Actual hours | L3: Overrun | M3: Start | N3: Actual end | O3: Team | P3: Modules | Q3: Notes
A4: P101 | B4: Patient portal v2 | C4: CareBridge Health | D4: US | E4: web | F4: .NET Core, React, SQL Server, Azure | G4: fixed | H4: USD | I4: 64900 | J4: 1972 | K4: 2274 | L4: =IF(J4>0,K4/J4-1,0) | M4: 2023-02-06 | N4: 2023-10-02 | O4: 3 | P4: auth, patient_records, booking, notifications, compliance, web_portal, cloud_infra | Q4: Delivered on time
A5: P102 | B5: Telehealth mobile app | C5: CareBridge Health | D5: US | E5: mobile | F5: React Native, Node.js, Twilio, AWS | G5: tm | H5: USD | I5: 52100 | J5: 1778 | K5: 2092 | L5: =IF(J5>0,K5/J5-1,0) | M5: 2024-04-01 | N5: 2024-11-04 | O5: 3 | P5: mobile_app, auth, booking, notifications, integration, compliance | Q5: App-store review added 2 weeks
A6: P103 | B6: Care-plan analytics dashboard | C6: MediLink Partners | D6: US | E6: bi | F6: Power BI, Azure SQL, Python | G6: fixed | H6: USD | I6: 27500 | J6: 773 | K6: 819 | L6: =IF(J6>0,K6/J6-1,0) | M6: 2022-09-05 | N6: 2022-12-26 | O6: 3 | P6: etl, reporting, auth, compliance | Q6: Delivered on time
A7: P104 | B7: Provider scheduling system | C7: MediLink Partners | D7: US | E7: web | F7: .NET Core, Angular, SQL Server | G7: fixed | H7: USD | I7: 39800 | J7: 1119 | K7: 1312 | L7: =IF(J7>0,K7/J7-1,0) | M7: 2024-08-12 | N7: 2025-01-27 | O7: 3 | P7: booking, auth, admin_panel, notifications, integration | Q7: UAT sign-off slow on client side
A8: P105 | B8: Wallets on the Fly | C8: PayNest | D8: UK | E8: mobile | F8: Flutter, Node.js, PostgreSQL, AWS | G8: tm | H8: GBP | I8: 49300 | J8: 2055 | K8: 2475 | L8: =IF(J8>0,K8/J8-1,0) | M8: 2021-03-01 | N8: 2022-01-10 | O8: 3 | P8: mobile_app, payments, auth, notifications, compliance, admin_panel | Q8: Device fragmentation drove extra QA
A9: P106 | B9: Merchant onboarding portal | C9: PayNest | D9: UK | E9: web | F9: React, .NET Core, Azure | G9: fixed | H9: GBP | I9: 24400 | J9: 950 | K9: 1061 | L9: =IF(J9>0,K9/J9-1,0) | M9: 2023-10-02 | N9: 2024-02-12 | O9: 3 | P9: web_portal, bpm, integration, auth | Q9: Scope creep in admin features
A10: P107 | B10: Machine monitoring dashboard | C10: Kraftwerk Maschinenbau GmbH | D10: DE | E10: iot | F10: Node.js, MQTT, InfluxDB, React, Azure | G10: fixed | H10: EUR | I10: 33400 | J10: 977 | K10: 1101 | L10: =IF(J10>0,K10/J10-1,0) | M10: 2022-01-10 | N10: 2022-07-11 | O10: 3 | P10: iot, reporting, realtime, auth, cloud_infra | Q10: Device firmware changes from client side
A11: P108 | B11: Spare-parts B2B ordering portal | C11: Kraftwerk Maschinenbau GmbH | D11: DE | E11: ecommerce | F11: .NET Core, Angular, SQL Server | G11: fixed | H11: EUR | I11: 31000 | J11: 1000 | K11: 1181 | L11: =IF(J11>0,K11/J11-1,0) | M11: 2024-11-04 | N11: 2025-04-07 | O11: 3 | P11: ecommerce, search, integration, auth, admin_panel | Q11: Catalog import edge cases
A12: P109 | B12: Coach booking platform | C12: Coachline Travel | D12: UK | E12: web | F12: PHP Laravel, Vue, MySQL, AWS | G12: fixed | H12: GBP | I12: 39200 | J12: 1508 | K12: 1716 | L12: =IF(J12>0,K12/J12-1,0) | M12: 2019-06-03 | N12: 2019-12-23 | O12: 3 | P12: booking, payments, search, web_portal, admin_panel, notifications | Q12: Delivered on time
A13: P110 | B13: Sightseeing tours mobile app | C13: Coachline Travel | D13: UK | E13: mobile | F13: React Native, Node.js, Stripe | G13: fixed | H13: GBP | I13: 35700 | J13: 1261 | K13: 1525 | L13: =IF(J13>0,K13/J13-1,0) | M13: 2023-05-08 | N13: 2023-10-09 | O13: 3 | P13: mobile_app, booking, payments, geo | Q13: Offline sync was underestimated
A14: P111 | B14: Adaptive learning platform (LMS) | C14: BrightPath Learning | D14: US | E14: web | F14: React, Python FastAPI, PostgreSQL, AWS | G14: tm | H14: USD | I14: 39600 | J14: 1290 | K14: 1496 | L14: =IF(J14>0,K14/J14-1,0) | M14: 2022-07-11 | N14: 2023-03-06 | O14: 3 | P14: web_portal, auth, cms, reporting, admin_panel | Q14: Scope creep in admin features
A15: P112 | B15: AI homework tutor (LLM) | C15: BrightPath Learning | D15: US | E15: ai | F15: Python, OpenAI API, RAG, React | G15: tm | H15: USD | I15: 33200 | J15: 968 | K15: 1284 | L15: =IF(J15>0,K15/J15-1,0) | M15: 2025-01-13 | N15: 2025-06-23 | O15: 3 | P15: llm_assistant, web_portal, auth, compliance | Q15: Hallucination guardrails added late
... A33: P130 | B33: Customer support RAG assistant | C33: PayNest | D33: UK | E33: ai | F33: Python, OpenAI API, PostgreSQL pgvector, React | G33: fixed | H33: GBP | I33: 26700 | J33: 896 | K33: 1162 | L33: =IF(J33>0,K33/J33-1,0) | M33: 2025-08-04 | N33: 2025-12-01 | O33: 3 | P33: llm_assistant, integration, compliance, admin_panel | Q33: Client changed the knowledge base mid-project
I34: All projects | J34: =SUM(J4:J33) | K34: =SUM(K4:K33) | L34: =IF(J34>0,K34/J34-1,0)

Sheet Past project modules
A1: Project | B1: Module | C1: Complexity | D1: Role | E1: Est. hours | F1: Actual hours
A2: P101 | B2: auth | C2: high | D2: ba | E2: 13.7 | F2: 15.2
A3: P101 | B3: auth | C3: high | D3: uiux | E3: 20.5 | F3: 22.8
A4: P101 | B4: auth | C4: high | D4: fe | E4: 68.4 | F4: 81.5
A5: P101 | B5: auth | C5: high | D5: be | E5: 95.8 | F5: 105.9
A6: P101 | B6: auth | C6: high | D6: qa | E6: 41.1 | F6: 44.4
A7: P101 | B7: patient_records | C7: high | D7: ba | E7: 68.2 | F7: 70.3
A8: P101 | B8: patient_records | C8: high | D8: fe | E8: 136.4 | F8: 157.9
A9: P101 | B9: patient_records | C9: high | D9: be | E9: 204.6 | F9: 252.3
A10: P101 | B10: patient_records | C10: high | D10: qa | E10: 95.5 | F10: 123.5
A11: P101 | B11: booking | C11: medium | D11: ba | E11: 26.5 | F11: 28.6
A12: P101 | B12: booking | C12: medium | D12: uiux | E12: 26.5 | F12: 27.8
A13: P101 | B13: booking | C13: medium | D13: fe | E13: 70.5 | F13: 83.5
... A621: P130 | B621: management | C621: medium | D621: lead | E621: 46.3 | F621: 47.9
